<?xml version="1.0" ?>
<!-- =================================================================================== -->
<!-- |    This document was autogenerated by xacro from /home/karagk/Workspaces/intrarobots_ws/src/robotic_arm_descriptions/urdf/kuka.urdf.xacro | -->
<!-- |    EDITING THIS FILE BY HAND IS NOT RECOMMENDED                                 | -->
<!-- =================================================================================== -->
<robot name="kuka">
  <gazebo>
    <plugin filename="libgazebo_ros_control.so" name="gazebo_ros_control">
      <robotSimType>gazebo_ros_control/DefaultRobotHWSim</robotSimType>
      <!-- <robotNameSpace>"$(arg robot_name)"</robotNameSpace> -->
      <!-- <legacyModeNS>true</legacyModeNS> -->
    </plugin>
  </gazebo>
  <gazebo reference="wx200/base_link">
    <material>Custom/Interbotix</material>
    <dampingFactor>0.1</dampingFactor>
  </gazebo>
  <gazebo reference="wx200/shoulder_link">
    <material>Custom/Interbotix</material>
    <dampingFactor>0.1</dampingFactor>
  </gazebo>
  <gazebo reference="wx200/upper_arm_link">
    <material>Custom/Interbotix</material>
    <dampingFactor>0.1</dampingFactor>
  </gazebo>
  <gazebo reference="wx200/forearm_link">
    <material>Custom/Interbotix</material>
    <dampingFactor>0.1</dampingFactor>
  </gazebo>
  <gazebo reference="wx200/upper_forearm_link">
    <material>Custom/Interbotix</material>
    <dampingFactor>0.1</dampingFactor>
  </gazebo>
  <gazebo reference="wx200/lower_forearm_link">
    <material>Custom/Interbotix</material>
    <dampingFactor>0.1</dampingFactor>
  </gazebo>
  <gazebo reference="wx200/wrist_link">
    <material>Custom/Interbotix</material>
    <dampingFactor>0.1</dampingFactor>
  </gazebo>
  <gazebo reference="wx200/gripper_link">
    <material>Custom/Interbotix</material>
    <dampingFactor>0.1</dampingFactor>
  </gazebo>
  <gazebo reference="wx200/gripper_prop_link">
    <material>Custom/Interbotix</material>
    <dampingFactor>0.1</dampingFactor>
  </gazebo>
  <gazebo reference="wx200/gripper_bar_link">
    <material>Custom/Interbotix</material>
  </gazebo>
  <gazebo reference="wx200/left_finger_link">
    <material>Custom/Interbotix</material>
    <dampingFactor>0.1</dampingFactor>
  </gazebo>
  <gazebo reference="wx200/right_finger_link">
    <material>Custom/Interbotix</material>
    <dampingFactor>0.1</dampingFactor>
  </gazebo>
  <gazebo reference="wx200/ar_tag_link">
    <material>Custom/Interbotix</material>
  </gazebo>
  <gazebo reference="ee_arm">
    <disableFixedJointLumping>true</disableFixedJointLumping>
  </gazebo>
  <gazebo reference="ar_tag">
    <disableFixedJointLumping>true</disableFixedJointLumping>
  </gazebo>
  <gazebo reference="gripper_bar">
    <disableFixedJointLumping>true</disableFixedJointLumping>
  </gazebo>
  <gazebo reference="ee_bar">
    <disableFixedJointLumping>true</disableFixedJointLumping>
  </gazebo>
  <gazebo reference="ee_gripper">
    <disableFixedJointLumping>true</disableFixedJointLumping>
  </gazebo>
  <material name="interbotix_black">
    <texture filename="package://interbotix_xsarm_descriptions/meshes/interbotix_black.png"/>
  </material>
  <!-- right is either 1 (for right arm) or -1 (for left arm) -->
  <link name="calib_kuka_arm_base_link">
    <visual>
      <origin rpy="0 0 0" xyz="0 0 0"/>
      <geometry>
        <mesh filename="package://interbotix_xsarm_descriptions/meshes/kuka_meshes/arm_base.stl"/>
      </geometry>
      <material name="interbotix_black"/>
    </visual>
    <collision>
      <origin rpy="0 0 0" xyz="0 0 0"/>
      <geometry>
        <mesh filename="package://interbotix_xsarm_descriptions/meshes/kuka_meshes/convex/arm_base_convex.stl"/>
      </geometry>
    </collision>
    <inertial>
      <mass value="2.0"/>
      <origin rpy="0 0 0" xyz="0 0 0.055"/>
      <inertia ixx="0.00381666666667" ixy="0" ixz="0" iyy="0.0036" iyz="0" izz="0.00381666666667"/>
    </inertial>
  </link>
  <gazebo reference="calib_kuka_arm_base_link">
    <kp>1000000.0</kp>
    <kd>1.0</kd>
    <mu1>0.8</mu1>
    <mu2>0.8</mu2>
    <maxVel>0.0</maxVel>
    <minDepth>0.001</minDepth>
  </gazebo>
  <joint name="kuka_arm_0_joint" type="revolute">
    <origin rpy="0 0 0" xyz="0 0 0.11"/>
    <axis xyz="0 0 1"/>
    <limit effort="176" lower="-2.96705972839" upper="2.96705972839" velocity="1.91986217719"/>
    <dynamics damping="1.0" friction="10.0"/>
    <parent link="calib_kuka_arm_base_link"/>
    <child link="kuka_arm_1_link"/>
  </joint>
  <link name="kuka_arm_1_link">
    <inertial>
      <mass value="2.35"/>
      <origin rpy="0 0 0" xyz="0 0.04 0.130"/>
      <inertia ixx="0.0136666666667" ixy="0" ixz="0" iyy="0.0118666666667" iyz="0" izz="0.003"/>
    </inertial>
    <visual>
      <origin rpy="0 0 3.14159265359" xyz="0 0 0"/>
      <geometry>
        <mesh filename="package://interbotix_xsarm_descriptions/meshes/kuka_meshes/arm_segment_a.stl"/>
      </geometry>
      <material name="interbotix_black"/>
    </visual>
    <collision>
      <origin rpy="0 0 3.14159265359" xyz="0 0 0"/>
      <geometry>
        <mesh filename="package://interbotix_xsarm_descriptions/meshes/kuka_meshes/convex/arm_segment_a_convex.stl"/>
      </geometry>
    </collision>
  </link>
  <transmission name="kuka_arm_0_trans">
    <type>pr2_mechanism_model/SimpleTransmission</type>
    <joint name="kuka_arm_0_joint">
      <hardwareInterface>hardware_interface/EffortJointInterface</hardwareInterface>
    </joint>
    <actuator name="kuka_arm_0_motor">
      <hardwareInterface>hardware_interface/EffortJointInterface</hardwareInterface>
      <mechanicalReduction>50</mechanicalReduction>
    </actuator>
  </transmission>
  <joint name="kuka_arm_1_joint" type="revolute">
    <origin rpy="0 0 0" xyz="0 0 0.20"/>
    <axis xyz="0 -1 0"/>
    <limit effort="176" lower="-1.57079632679" upper="1.57079632679" velocity="1.91986217719"/>
    <dynamics damping="1.0" friction="10.0"/>
    <parent link="kuka_arm_1_link"/>
    <child link="kuka_arm_2_link"/>
  </joint>
  <link name="kuka_arm_2_link">
    <inertial>
      <mass value="2.35"/>
      <origin rpy="0 0 0" xyz="0 -0.04 0.07"/>
      <inertia ixx="0.0136666666667" ixy="0" ixz="0" iyy="0.0118666666667" iyz="0" izz="0.003"/>
    </inertial>
    <visual>
      <origin rpy="3.14159265359 0 3.14159265359" xyz="0 0 0.2"/>
      <geometry>
        <mesh filename="package://interbotix_xsarm_descriptions/meshes/kuka_meshes/arm_segment_b.stl"/>
      </geometry>
      <material name="interbotix_black"/>
    </visual>
    <collision>
      <origin rpy="3.14159265359 0 3.14159265359" xyz="0 0 0.2"/>
      <geometry>
        <mesh filename="package://interbotix_xsarm_descriptions/meshes/kuka_meshes/convex/arm_segment_b_convex.stl"/>
      </geometry>
    </collision>
  </link>
  <transmission name="kuka_arm_1_trans">
    <type>pr2_mechanism_model/SimpleTransmission</type>
    <joint name="kuka_arm_1_joint">
      <hardwareInterface>hardware_interface/EffortJointInterface</hardwareInterface>
    </joint>
    <actuator name="kuka_arm_1_motor">
      <hardwareInterface>hardware_interface/EffortJointInterface</hardwareInterface>
      <mechanicalReduction>50</mechanicalReduction>
    </actuator>
  </transmission>
  <joint name="kuka_arm_2_joint" type="revolute">
    <origin rpy="0 0 0" xyz="0 0 0.20"/>
    <axis xyz="0 0 1"/>
    <limit effort="100" lower="-2.96705972839" upper="2.96705972839" velocity="2.26892802759"/>
    <dynamics damping="1.0" friction="10.0"/>
    <parent link="kuka_arm_2_link"/>
    <child link="kuka_arm_3_link"/>
  </joint>
  <link name="kuka_arm_3_link">
    <inertial>
      <mass value="2.35"/>
      <origin rpy="0 0 0" xyz="0 -0.04 0.130"/>
      <inertia ixx="0.0136666666667" ixy="0" ixz="0" iyy="0.0118666666667" iyz="0" izz="0.003"/>
    </inertial>
    <visual>
      <origin rpy="0 0 0" xyz="0 0 0"/>
      <geometry>
        <mesh filename="package://interbotix_xsarm_descriptions/meshes/kuka_meshes/arm_segment_a.stl"/>
      </geometry>
      <material name="interbotix_black"/>
    </visual>
    <collision>
      <origin rpy="0 0 0" xyz="0 0 0"/>
      <geometry>
        <mesh filename="package://interbotix_xsarm_descriptions/meshes/kuka_meshes/convex/arm_segment_a_convex.stl"/>
      </geometry>
    </collision>
  </link>
  <transmission name="kuka_arm_2_trans">
    <type>pr2_mechanism_model/SimpleTransmission</type>
    <joint name="kuka_arm_2_joint">
      <hardwareInterface>hardware_interface/EffortJointInterface</hardwareInterface>
    </joint>
    <actuator name="kuka_arm_2_motor">
      <hardwareInterface>hardware_interface/EffortJointInterface</hardwareInterface>
      <mechanicalReduction>50</mechanicalReduction>
    </actuator>
  </transmission>
  <joint name="kuka_arm_3_joint" type="revolute">
    <origin rpy="0 0 0" xyz="0 0 0.20"/>
    <axis xyz="0 1 0"/>
    <limit effort="100" lower="-2.09439510239" upper="2.09439510239" velocity="2.26892802759"/>
    <dynamics damping="1.0" friction="10.0"/>
    <parent link="kuka_arm_3_link"/>
    <child link="kuka_arm_4_link"/>
  </joint>
  <link name="kuka_arm_4_link">
    <inertial>
      <mass value="2.35"/>
      <origin rpy="0 0 0" xyz="0 0.04 0.07"/>
      <inertia ixx="0.0136666666667" ixy="0" ixz="0" iyy="0.0118666666667" iyz="0" izz="0.003"/>
    </inertial>
    <visual>
      <origin rpy="0 3.14159265359 3.14159265359" xyz="0 0 0.2"/>
      <geometry>
        <mesh filename="package://interbotix_xsarm_descriptions/meshes/kuka_meshes/arm_segment_b.stl"/>
      </geometry>
      <material name="interbotix_black"/>
    </visual>
    <collision>
      <origin rpy="0 3.14159265359 3.14159265359" xyz="0 0 0.2"/>
      <geometry>
        <mesh filename="package://interbotix_xsarm_descriptions/meshes/kuka_meshes/convex/arm_segment_b_convex.stl"/>
      </geometry>
    </collision>
  </link>
  <transmission name="kuka_arm_3_trans">
    <type>pr2_mechanism_model/SimpleTransmission</type>
    <joint name="kuka_arm_3_joint">
      <hardwareInterface>hardware_interface/EffortJointInterface</hardwareInterface>
    </joint>
    <actuator name="kuka_arm_3_motor">
      <hardwareInterface>hardware_interface/EffortJointInterface</hardwareInterface>
      <mechanicalReduction>50</mechanicalReduction>
    </actuator>
  </transmission>
  <joint name="kuka_arm_4_joint" type="revolute">
    <origin rpy="0 0 0" xyz="0 0 0.20"/>
    <axis xyz="0 0 1"/>
    <limit effort="100" lower="-2.96705972839" upper="2.96705972839" velocity="2.26892802759"/>
    <dynamics damping="1.0" friction="10.0"/>
    <parent link="kuka_arm_4_link"/>
    <child link="kuka_arm_5_link"/>
  </joint>
  <link name="kuka_arm_5_link">
    <inertial>
      <mass value="2.35"/>
      <origin rpy="0 0 0" xyz="0 0.02 0.124"/>
      <inertia ixx="0.0126506666667" ixy="0" ixz="0" iyy="0.0108506666667" iyz="0" izz="0.003"/>
    </inertial>
    <visual>
      <origin rpy="0 0 3.14159265359" xyz="0 0 0"/>
      <geometry name="kuka_arm_5_geom">
        <mesh filename="package://interbotix_xsarm_descriptions/meshes/kuka_meshes/arm_segment_last.stl"/>
      </geometry>
      <material name="interbotix_black"/>
    </visual>
    <collision>
      <origin rpy="0 0 3.14159265359" xyz="0 0 0"/>
      <geometry>
        <mesh filename="package://interbotix_xsarm_descriptions/meshes/kuka_meshes/convex/arm_segment_last_convex.stl"/>
      </geometry>
    </collision>
  </link>
  <transmission name="kuka_arm_4_trans">
    <type>pr2_mechanism_model/SimpleTransmission</type>
    <joint name="kuka_arm_4_joint">
      <hardwareInterface>hardware_interface/EffortJointInterface</hardwareInterface>
    </joint>
    <actuator name="kuka_arm_4_motor">
      <hardwareInterface>hardware_interface/EffortJointInterface</hardwareInterface>
      <mechanicalReduction>50</mechanicalReduction>
    </actuator>
  </transmission>
  <joint name="kuka_arm_5_joint" type="revolute">
    <origin rpy="0 0 0" xyz="0 0 0.19"/>
    <axis xyz="0 -1 0"/>
    <limit effort="38" lower="-2.09439510239" upper="2.09439510239" velocity="3.14159265359"/>
    <dynamics damping="1.0" friction="10.0"/>
    <parent link="kuka_arm_5_link"/>
    <child link="kuka_arm_6_link"/>
  </joint>
  <link name="kuka_arm_6_link">
    <inertial>
      <mass value="1.1"/>
      <origin rpy="0 0 0" xyz="0 0 0"/>
      <inertia ixx="0.00520833333333" ixy="0" ixz="0" iyy="0.00520833333333" iyz="0" izz="0.00520833333333"/>
    </inertial>
    <visual>
      <origin rpy="0 0 3.14159265359" xyz="0 0 0"/>
      <geometry>
        <mesh filename="package://interbotix_xsarm_descriptions/meshes/kuka_meshes/arm_wrist.stl"/>
      </geometry>
      <material name="interbotix_black"/>
    </visual>
    <collision>
      <origin rpy="0 0 3.14159265359" xyz="0 0 0"/>
      <geometry>
        <mesh filename="package://interbotix_xsarm_descriptions/meshes/kuka_meshes/convex/arm_wrist_convex.stl"/>
      </geometry>
    </collision>
  </link>
  <transmission name="kuka_arm_5_trans">
    <type>pr2_mechanism_model/SimpleTransmission</type>
    <joint name="kuka_arm_5_joint">
      <hardwareInterface>hardware_interface/EffortJointInterface</hardwareInterface>
    </joint>
    <actuator name="kuka_arm_5_motor">
      <hardwareInterface>hardware_interface/EffortJointInterface</hardwareInterface>
      <mechanicalReduction>50</mechanicalReduction>
    </actuator>
  </transmission>
  <joint name="kuka_arm_6_joint" type="revolute">
    <origin rpy="0 0 0" xyz="0 0 0.078"/>
    <axis xyz="0 0 1"/>
    <limit effort="38" lower="-2.96705972839" upper="2.96705972839" velocity="3.14159265359"/>
    <dynamics damping="1.0" friction="10.0"/>
    <parent link="kuka_arm_6_link"/>
    <child link="kuka_arm_7_link"/>
  </joint>
  <link name="kuka_arm_7_link">
    <inertial>
      <mass value="0.25"/>
      <origin xyz="0 0 0"/>
      <inertia ixx="0.000833333333333" ixy="0" ixz="0" iyy="0.000833333333333" iyz="0" izz="0.000833333333333"/>
    </inertial>
    <visual>
      <origin rpy="0 0 3.14159265359" xyz="0 0 0"/>
      <geometry>
        <mesh filename="package://interbotix_xsarm_descriptions/meshes/kuka_meshes/arm_flanche.stl"/>
      </geometry>
      <material name="interbotix_black"/>
    </visual>
    <collision>
      <origin rpy="0 0 3.14159265359" xyz="0 0 0"/>
      <geometry>
        <mesh filename="package://interbotix_xsarm_descriptions/meshes/kuka_meshes/convex/arm_flanche_convex.stl"/>
      </geometry>
    </collision>
  </link>
  <transmission name="kuka_arm_6_trans">
    <type>pr2_mechanism_model/SimpleTransmission</type>
    <joint name="kuka_arm_6_joint">
      <hardwareInterface>hardware_interface/EffortJointInterface</hardwareInterface>
    </joint>
    <actuator name="kuka_arm_6_motor">
      <hardwareInterface>hardware_interface/EffortJointInterface</hardwareInterface>
      <mechanicalReduction>50</mechanicalReduction>
    </actuator>
  </transmission>
</robot>

